Workbook
Name advance_rate: Inputs!$B$22
Name avg_ticket_k: Inputs!$B$9
Name cof_apr: Scenarios!$B$9
Name disb_y1: Inputs!$B$6
Name disb_y2: Inputs!$B$7
Name disb_y3: Scenarios!$B$5
Name disb_y4: Inputs!$B$37
Name disb_y5: Inputs!$B$38
Name ead_bnpl: Risk!$C$7
Name ead_ext: Risk!$D$7
Name ead_pay30: Risk!$B$7
Name equity_pct: Inputs!$B$32
Name fee_bnpl_mo: Scenarios!$B$7
Name fee_ext_apr: Scenarios!$B$8
Name fee_pay30_mo: Scenarios!$B$6
Name lgd_bnpl: Risk!$C$6
Name lgd_ext: Risk!$D$6
Name lgd_pay30: Risk!$B$6
Name mix_bnpl: Inputs!$B$12
Name mix_ext: Inputs!$B$13
Name mix_pay30: Inputs!$B$11
Name opex_pct: Scenarios!$B$13
Name opex_y1_mult: Inputs!$B$34
Name opex_y2_mult: Inputs!$B$35
Name opex_y3_mult: Inputs!$B$36
Name opex_y4_mult: Inputs!$B$39
Name opex_y5_mult: Inputs!$B$40
Name pd_bnpl: Scenarios!$B$11
Name pd_ext: Scenarios!$B$12
Name pd_pay30: Scenarios!$B$10
Name tenor_bnpl: Inputs!$B$16
Name tenor_ext: Inputs!$B$17
Name tenor_pay30: Inputs!$B$15

Sheet Guide
A1: Mal · Product 1 · Smart Invoice
A2: Invoice Discount + BNPL embedded + Flexible Tenure embedded
A3: Currency: AED · Unit: M (millions) unless noted · Time: annualised
A6: Purpose | B6: Canonical financial model for Mal Smart Invoice. Source of truth for the prototype viewer in section-financial.jsx. Hand to Anthropic Model Builder / Valuation Reviewer agents in Claude.ai for stress-testing and scenario expansion.
A7: Structure | B7: Inputs (editable) → Volume & Mix → 3 track P&Ls (Pay-30, BNPL, Term Extension) → Combined → Unit Economics → Sensitivity → Validation. Each track P&L is identical in shape so agents can compare them.
A8: Editing | B8: Lilac cells = inputs (edit these). Paper cells = formulas (do not overwrite). Sage cells = key outputs. Named ranges defined for every input — see Formulas tab in Excel.
A10: UAE benchmarks used
A11: Cost of funds | B11: 3M EIBOR ~5.10–5.30% (May 2026). NBFI spread 1.0–1.5% over EIBOR for senior unsecured. Use 6.5%. Sources: CBUAE Monetary Bulletin Q1 2026; Fitch UAE Banks 2026 outlook.
A12: Discount fee (1.3%/mo) | B12: UAE SME factoring market: 1.5–3.0%/mo. Mashreq Trade, CBI Trade, ENBD Business Banking SCF: ~1.5–2.2%/mo. eFunder, Bridgr (UAE NBFC): 1.8–2.8%/mo. Mal at 1.3%/mo (15.6% APR) sits intentionally below market band — embedded-checkout convenience premium without consumer-style pricing on SME book. Source: FSRA NBFC pricing reviews; broker-dealer trade-finance schedules.
A13: BNPL fee (1.5%/mo) | B13: Consumer BNPL (Tabby/Tamara/Postpay): 3.0–3.5%/mo flat to merchant. B2B BNPL (Sympl, ToYou Pay Later): 2.0–2.8%/mo. Mal at 1.5%/mo (18% APR) reflects supplier-discount blend embedded in checkout flow vs standalone B2B BNPL. Tightened from 1.8% to keep headline RAROC defensible. Source: company T&Cs, MoF B2B BNPL guidelines 2025.
A14: Risk: PD×LGD×EAD framework | B14: Pay-30: PD 2.0%, LGD 25% (invoice collateral). BNPL: PD 4.0%, LGD 45%. Extension: PD 10.0%, LGD 65% (unsecured workout). EAD 100% (no undrawn). Net loss rate blended 2.6% on book. Source: Basel III IRB foundation; CBUAE FSR 2025 §3.4; Moody's UAE Banking 2026.
A15: Term extension (16% APR) | B15: Restructured/workout SME credit in UAE: 16–22% APR depending on collateral. CBUAE allows distressed-credit pricing up to consumer-protection caps. Note: 16% sits at low end — see Validation sheet for risk-priced alternative at 19%.
A16: OpEx (2.4% of book) | B16: Mature UAE factor: 1.5–2.5% of book. Early-stage fintech lender: 4–6% Y1 falling to 2–3% Y3. Mal trajectory plausible if scaling per disbursement plan. Source: NBFC public filings (Reem Finance, Aafaq); Strategy& UAE fintech benchmarks 2025.
A17: Equity (14% of book) | B17: CBUAE Capital Adequacy minimum: 10.5% CET1 + 2.5% conservation buffer = 13% Tier-1 standard. NBFCs: 10–15%. Mal at 14% adds 1-pt CRO management buffer above standard — 7.14× leverage vs 8.33× at 12% equity. Source: CBUAE Reg 32/2013 amended 2024; Basel III local implementation.
A18: Advance rate (90%) | B18: UAE invoice discount norm: 80–95% of face. 90% standard for prime obligor. Higher for anchor-validated invoices. Source: Mashreq SCF, CBI Working Capital schedules.
A19: Avg ticket (AED 80k) | B19: UAE SME invoice median 50–120k (DED registry data inferred). Mal target segment trade/services. Source: Strategy doc Section 4.2.
A20: Avg tenor (75 days) | B20: Blended: Pay-30 (40% mix), BNPL 60-180 (50% mix avg ~90d), Extension 6-mo (10% mix). Weighted = 75d.
A22: Last updated | B22: =TODAY() -> 46152
A23: Bench-marks NOT yet validated against Moody's | B23: Phase 2: replace defaultRatePct per track with PD/LGD/EAD curves from Moody's MCP for actual UAE private-company ratings distribution.

Sheet Dashboard
A1: Mal · Smart Invoice
A2: Live view of the canonical financial model. All figures recompute when Inputs / Risk Layer / Scenarios change.
B4: Y3 Disbursement | D4: Y3 Net Income | F4: Y3 RAROC (post-tax) | H4: Y1→Y5 Cum Net Income | J4: Y5 Equity Required
B5: =disb_y3 -> 4000 | D5: ='Combined P&L'!D35 -> 26.328419 | F5: ='Combined P&L'!D38 -> 23.111768 | H5: =SUM('Combined P&L'!B35:F35) -> 199.15311 | J5: ='Combined P&L'!F13 -> 370.23288
B6: AED M (face) | D6: AED M (post-tax) | F6: on equity | H6: AED M (post-tax 5-yr) | J6: AED M (Tier-1 base)
B27: Y3 Net Contribution sensitivity · Default rate × Cost of funds
B28: Live mirror of Sensitivity sheet · lilac = best, danger = worst
B30: =Sensitivity!A4 -> PD × → / COF ↓ | C30: =Sensitivity!B4 -> 0.6× PD | D30: =Sensitivity!C4 -> 0.8× PD | E30: =Sensitivity!D4 -> 1.0× PD | F30: =Sensitivity!E4 -> 1.2× PD | G30: =Sensitivity!F4 -> 1.5× PD | H30: =Sensitivity!G4 -> 1.8× PD | I30: =Sensitivity!H4 -> 2.2× PD
B31: =Sensitivity!A5 -> COF 5.5% | C31: =Sensitivity!B5 -> 62.779068 | D31: =Sensitivity!C5 -> 58.441315 | E31: =Sensitivity!D5 -> 54.103562 | F31: =Sensitivity!E5 -> 49.765808 | G31: =Sensitivity!F5 -> 43.259178 | H31: =Sensitivity!G5 -> 36.752548 | I31: =Sensitivity!H5 -> 28.077041
B32: =Sensitivity!A6 -> COF 6.0% | C32: =Sensitivity!B6 -> 58.710575 | D32: =Sensitivity!C6 -> 54.372822 | E32: =Sensitivity!D6 -> 50.035068 | F32: =Sensitivity!E6 -> 45.697315 | G32: =Sensitivity!F6 -> 39.190685 | H32: =Sensitivity!G6 -> 32.684055 | I32: =Sensitivity!H6 -> 24.008548
B33: =Sensitivity!A7 -> COF 6.5% | C33: =Sensitivity!B7 -> 54.642082 | D33: =Sensitivity!C7 -> 50.304329 | E33: =Sensitivity!D7 -> 45.966575 | F33: =Sensitivity!E7 -> 41.628822 | G33: =Sensitivity!F7 -> 35.122192 | H33: =Sensitivity!G7 -> 28.615562 | I33: =Sensitivity!H7 -> 19.940055
B34: =Sensitivity!A8 -> COF 7.0% | C34: =Sensitivity!B8 -> 50.573589 | D34: =Sensitivity!C8 -> 46.235836 | E34: =Sensitivity!D8 -> 41.898082 | F34: =Sensitivity!E8 -> 37.560329 | G34: =Sensitivity!F8 -> 31.053699 | H34: =Sensitivity!G8 -> 24.547068 | I34: =Sensitivity!H8 -> 15.871562
B35: =Sensitivity!A9 -> COF 7.5% | C35: =Sensitivity!B9 -> 46.505096 | D35: =Sensitivity!C9 -> 42.167342 | E35: =Sensitivity!D9 -> 37.829589 | F35: =Sensitivity!E9 -> 33.491836 | G35: =Sensitivity!F9 -> 26.985205 | H35: =Sensitivity!G9 -> 20.478575 | I35: =Sensitivity!H9 -> 11.803068
B36: =Sensitivity!A10 -> COF 8.0% | C36: =Sensitivity!B10 -> 42.436603 | D36: =Sensitivity!C10 -> 38.098849 | E36: =Sensitivity!D10 -> 33.761096 | F36: =Sensitivity!E10 -> 29.423342 | G36: =Sensitivity!F10 -> 22.916712 | H36: =Sensitivity!G10 -> 16.410082 | I36: =Sensitivity!H10 -> 7.7345753
B37: =Sensitivity!A11 -> COF 8.5% | C37: =Sensitivity!B11 -> 38.36811 | D37: =Sensitivity!C11 -> 34.030356 | E37: =Sensitivity!D11 -> 29.692603 | F37: =Sensitivity!E11 -> 25.354849 | G37: =Sensitivity!F11 -> 18.848219 | H37: =Sensitivity!G11 -> 12.341589 | I37: =Sensitivity!H11 -> 3.6660822
A40: Chart data (do not delete)
A42: Disbursement by track (AED M, face value)
A43: Track | B43: Y1 | C43: Y2 | D43: Y3 | E43: Y4 | F43: Y5
A44: Pay-30 | B44: ='Volume & Mix'!B5*mix_pay30/100 -> 100 | C44: ='Volume & Mix'!C5*mix_pay30/100 -> 600 | D44: ='Volume & Mix'!D5*mix_pay30/100 -> 1600 | E44: ='Volume & Mix'!E5*mix_pay30/100 -> 3200 | F44: ='Volume & Mix'!F5*mix_pay30/100 -> 5200
A45: BNPL | B45: ='Volume & Mix'!B5*mix_bnpl/100 -> 125 | C45: ='Volume & Mix'!C5*mix_bnpl/100 -> 750 | D45: ='Volume & Mix'!D5*mix_bnpl/100 -> 2000 | E45: ='Volume & Mix'!E5*mix_bnpl/100 -> 4000 | F45: ='Volume & Mix'!F5*mix_bnpl/100 -> 6500
A46: Term Extension | B46: ='Volume & Mix'!B5*mix_ext/100 -> 25 | C46: ='Volume & Mix'!C5*mix_ext/100 -> 150 | D46: ='Volume & Mix'!D5*mix_ext/100 -> 400 | E46: ='Volume & Mix'!E5*mix_ext/100 -> 800 | F46: ='Volume & Mix'!F5*mix_ext/100 -> 1300
A48: P&L margins (% of book)
A49: Metric | B49: Y1 | C49: Y2 | D49: Y3 | E49: Y4 | F49: Y5
A50: NIM % | B50: ='Combined P&L'!B16 -> 10.714545 | C50: ='Combined P&L'!C16 -> 10.714545 | D50: ='Combined P&L'!D16 -> 10.714545 | E50: ='Combined P&L'!E16 -> 10.714545 | F50: ='Combined P&L'!F16 -> 10.714545
A51: Loss rate % | B51: ='Combined P&L'!B17 -> 2.6654545 | C51: ='Combined P&L'!C17 -> 2.6654545 | D51: ='Combined P&L'!D17 -> 2.6654545 | E51: ='Combined P&L'!E17 -> 2.6654545 | F51: ='Combined P&L'!F17 -> 2.6654545
A52: OpEx % | B52: ='Combined P&L'!B18 -> 4.008 | C52: ='Combined P&L'!C18 -> 3 | D52: ='Combined P&L'!D18 -> 2.4 | E52: ='Combined P&L'!E18 -> 2.28 | F52: ='Combined P&L'!F18 -> 2.208
A53: Net margin % | B53: ='Combined P&L'!B19 -> 23.474863 | C53: ='Combined P&L'!C19 -> 29.330376 | D53: ='Combined P&L'!D19 -> 32.815801 | E53: ='Combined P&L'!E19 -> 33.512886 | F53: ='Combined P&L'!F19 -> 33.931136
A55: Returns (% / % on equity)
A56: Metric | B56: Y1 | C56: Y2 | D56: Y3 | E56: Y4 | F56: Y5
A57: ROA | B57: ='Combined P&L'!B20 -> 4.0410909 | C57: ='Combined P&L'!C20 -> 5.0490909 | D57: ='Combined P&L'!D20 -> 5.6490909 | E57: ='Combined P&L'!E20 -> 5.7690909 | F57: ='Combined P&L'!F20 -> 5.8410909
A58: RAROC | B58: ='Combined P&L'!B21 -> 28.864935 | C58: ='Combined P&L'!C21 -> 36.064935 | D58: ='Combined P&L'!D21 -> 40.350649 | E58: ='Combined P&L'!E21 -> 41.207792 | F58: ='Combined P&L'!F21 -> 41.722078

Sheet Inputs
A1: Inputs · Smart Invoice
A2: Edit lilac cells. Named ranges available — see formulas in track P&L sheets.
A4: Assumption | B4: Value | C4: Unit | E4: Named range | F4: Validation note
A5: Volume
A6: Disbursement Y1 | B6: 250 | C6: AED M | E6: disb_y1 | F6: Strategy doc Section 5.1 — Y1 plan.
A7: Disbursement Y2 | B7: 1500 | C7: AED M | E7: disb_y2 | F7: Strategy doc Section 5.1 — Y2 plan.
A8: Disbursement Y3 | B8: 4000 | C8: AED M | E8: disb_y3 | F8: Strategy doc Section 5.1 — Y3 plan.
A9: Avg ticket size | B9: 80 | C9: AED K | E9: avg_ticket_k | F9: UAE SME invoice median 50–120k.
A10: Mix
A11: Pay-30 share of book | B11: 40 | C11: % | E11: mix_pay30 | F11: Buyer plan picker default; demo flow data.
A12: BNPL share of book | B12: 50 | C12: % | E12: mix_bnpl | F12: Pay-60/90/120/180 plans blended.
A13: Term Extension share | B13: 10 | C13: % | E13: mix_ext | F13: Extension penetration ~22% × Pay-30 share.
A14: Tenor
A15: Pay-30 avg tenor | B15: 30 | C15: days | E15: tenor_pay30 | F15: Single-bullet 30-day pay.
A16: BNPL avg tenor | B16: 105 | C16: days | E16: tenor_bnpl | F16: Weighted avg of 60/90/120/180 plans.
A17: Term Extension tenor | B17: 180 | C17: days | E17: tenor_ext | F17: 6-month restructure schedule.
A18: Pricing
A19: Pay-30 discount fee | B19: 1.3 | C19: % per month | E19: fee_pay30_mo | F19: Tightened from 1.6 — prevents consumer-style pricing on SME book. Mashreq SCF / CBI Trade band 1.5-2.2%/mo; Mal floors below band on embedded-checkout convenience premium.
A20: BNPL fee | B20: 1.5 | C20: % per month | E20: fee_bnpl_mo | F20: Tightened from 1.8 — B2B BNPL UAE band 2.0-2.8%/mo; 1.5% reflects supplier-discount blend, embedded-platform play.
A21: Term Extension APR | B21: 16 | C21: % | E21: fee_ext_apr | F21: 16% low end. See Validation for 19% risk-priced alt.
A22: Advance rate | B22: 90 | C22: % of invoice | E22: advance_rate | F22: UAE norm 80–95%; 90% prime obligor.
A23: Cost
A24: Cost of funds | B24: 6.5 | C24: % APR | E24: cof_apr | F24: EIBOR ~5.2% + NBFI spread 1.3% = 6.5%.
A25: OpEx (% of avg book) | B25: 2.4 | C25: % | E25: opex_pct | F25: Y3 mature; ramps 4.0/3.0/2.4 per JSX.
A26: Risk
A27: Pay-30 net loss rate (display) | B27: =Risk!B9 -> 0.7 | C27: % of book | E27: (display only) | F27: Derived: PD×LGD×EAD. Authoritative source = Risk Layer.
A28: BNPL net loss rate (display) | B28: =Risk!C9 -> 1.8 | C28: % of book | E28: (display only) | F28: Derived: PD×LGD×EAD. Authoritative source = Risk Layer.
A29: Term Extension net loss rate (display) | B29: =Risk!D9 -> 6.5 | C29: % of book | E29: (display only) | F29: Derived: PD×LGD×EAD. Authoritative source = Risk Layer.
A30: (deprecated — was "Recovery %") | F30: Replaced by per-track LGDs on Risk Layer (25/45/65). Row kept as audit trail.
A31: Capital
A32: Equity (% of avg book) | B32: 14 | C32: % | E32: equity_pct | F32: Tightened from 12% — CBUAE Tier-1 floor 10.5% CET1 + 2.5% conservation = 13% standard; Mal at 14% adds 1-pt CRO management buffer.
A33: OpEx ramp
A34: OpEx Y1 multiplier | B34: 1.67 | C34: x of base | E34: opex_y1_mult | F34: Y1 = 4.0% / 2.4% = 1.67x.
A35: OpEx Y2 multiplier | B35: 1.25 | C35: x of base | E35: opex_y2_mult | F35: Y2 = 3.0% / 2.4% = 1.25x.
A36: OpEx Y3 multiplier | B36: 1 | C36: x of base | E36: opex_y3_mult | F36: Y3 = 2.4% (mature).
A37: Disbursement Y4 | B37: 8000 | C37: AED M | E37: disb_y4 | F37: Five-year extension; growth tapering from Y3 trajectory.
A38: Disbursement Y5 | B38: 13000 | C38: AED M | E38: disb_y5 | F38: Five-year extension; mature scale assumption.
A39: OpEx Y4 multiplier | B39: 0.95 | C39: x of base | E39: opex_y4_mult | F39: Y4 = 2.4% × 0.95 = 2.28% — operating leverage.
A40: OpEx Y5 multiplier | B40: 0.92 | C40: x of base | E40: opex_y5_mult | F40: Y5 = 2.4% × 0.92 = 2.21% — continued leverage.

Sheet Volume & Mix
A1: Volume & Average Book per Track
A2: book = disbursement × advance_rate × tenor / 365 × mix_share
A4: Item | B4: Y1 | C4: Y2 | D4: Y3 | E4: Y4 | F4: Y5 | H4: Notes
A5: Disbursement (face value) | B5: =disb_y1 -> 250 | C5: =disb_y2 -> 1500 | D5: =disb_y3 -> 4000 | E5: =disb_y4 -> 8000 | F5: =disb_y5 -> 13000 | H5: AED M
A6: Advanced principal | B6: =disb_y1*advance_rate/100 -> 225 | C6: =disb_y2*advance_rate/100 -> 1350 | D6: =disb_y3*advance_rate/100 -> 3600 | E6: =disb_y4*advance_rate/100 -> 7200 | F6: =disb_y5*advance_rate/100 -> 11700 | H6: disb × advance_rate
A8: Per-track average book (AED M)
A9: Pay-30 book | B9: =disb_y1*advance_rate/100*tenor_pay30/365*mix_pay30/100 -> 7.3972603 | C9: =disb_y2*advance_rate/100*tenor_pay30/365*mix_pay30/100 -> 44.383562 | D9: =disb_y3*advance_rate/100*tenor_pay30/365*mix_pay30/100 -> 118.35616 | E9: =disb_y4*advance_rate/100*tenor_pay30/365*mix_pay30/100 -> 236.71233 | F9: =disb_y5*advance_rate/100*tenor_pay30/365*mix_pay30/100 -> 384.65753 | H9: mix_pay30 share, 30-day tenor
A10: BNPL book | B10: =disb_y1*advance_rate/100*tenor_bnpl/365*mix_bnpl/100 -> 32.363014 | C10: =disb_y2*advance_rate/100*tenor_bnpl/365*mix_bnpl/100 -> 194.17808 | D10: =disb_y3*advance_rate/100*tenor_bnpl/365*mix_bnpl/100 -> 517.80822 | E10: =disb_y4*advance_rate/100*tenor_bnpl/365*mix_bnpl/100 -> 1035.6164 | F10: =disb_y5*advance_rate/100*tenor_bnpl/365*mix_bnpl/100 -> 1682.8767 | H10: mix_bnpl share, 105-day blended tenor
A11: Term Extension book | B11: =disb_y1*advance_rate/100*tenor_ext/365*mix_ext/100 -> 11.09589 | C11: =disb_y2*advance_rate/100*tenor_ext/365*mix_ext/100 -> 66.575342 | D11: =disb_y3*advance_rate/100*tenor_ext/365*mix_ext/100 -> 177.53425 | E11: =disb_y4*advance_rate/100*tenor_ext/365*mix_ext/100 -> 355.06849 | F11: =disb_y5*advance_rate/100*tenor_ext/365*mix_ext/100 -> 576.9863 | H11: mix_ext share, 180-day tenor
A13: Total avg book | B13: =SUM(B9:B11) -> 50.856164 | C13: =SUM(C9:C11) -> 305.13699 | D13: =SUM(D9:D11) -> 813.69863 | E13: =SUM(E9:E11) -> 1627.3973 | F13: =SUM(F9:F11) -> 2644.5205 | H13: sum of tracks

Sheet Disbursement Plan
A1: Disbursement Plan · 5-year trajectory
A2: Strategy doc Sections 5.1 — figures locked unless flagged. Sourced from disb_y1..disb_y5.
A4: Line (AED M) | B4: Y1 | C4: Y2 | D4: Y3 | E4: Y4 | F4: Y5 | G4: Y1→Y5 CAGR | H4: Notes
A5: Disbursement (face) | B5: =disb_y1 -> 250 | C5: =disb_y2 -> 1500 | D5: =disb_y3 -> 4000 | E5: =disb_y4 -> 8000 | F5: =disb_y5 -> 13000 | G5: =(F5/B5)^(1/4)-1 -> 1.6853496 | H5: AED M invoice face value disbursed
A6: YoY growth | C6: =C5/B5-1 -> 5 | D6: =D5/C5-1 -> 1.6666667 | E6: =E5/D5-1 -> 1 | F6: =F5/E5-1 -> 0.625 | H6: Strategy: 6.0x → 2.7x → 2.0x → 1.6x ramp
A8: Advanced principal | B8: =B5*advance_rate/100 -> 225 | C8: =C5*advance_rate/100 -> 1350 | D8: =D5*advance_rate/100 -> 3600 | E8: =E5*advance_rate/100 -> 7200 | F8: =F5*advance_rate/100 -> 11700 | G8: =(F8/B8)^(1/4)-1 -> 1.6853496 | H8: = face × advance_rate (90%)
A10: Total avg book | B10: ='Volume & Mix'!B13 -> 50.856164 | C10: ='Volume & Mix'!C13 -> 305.13699 | D10: ='Volume & Mix'!D13 -> 813.69863 | E10: ='Volume & Mix'!E13 -> 1627.3973 | F10: ='Volume & Mix'!F13 -> 2644.5205 | G10: =(F10/B10)^(1/4)-1 -> 1.6853496 | H10: Weighted by mix × tenor
A12: Composition (% of book)
A13: Pay-30 share | B13: ='Volume & Mix'!B9/'Volume & Mix'!B13 -> 0.14545455 | C13: ='Volume & Mix'!C9/'Volume & Mix'!C13 -> 0.14545455 | D13: ='Volume & Mix'!D9/'Volume & Mix'!D13 -> 0.14545455 | E13: ='Volume & Mix'!E9/'Volume & Mix'!E13 -> 0.14545455 | F13: ='Volume & Mix'!F9/'Volume & Mix'!F13 -> 0.14545455 | H13: 30-day tenor weight is small in book share
A14: BNPL share | B14: ='Volume & Mix'!B10/'Volume & Mix'!B13 -> 0.63636364 | C14: ='Volume & Mix'!C10/'Volume & Mix'!C13 -> 0.63636364 | D14: ='Volume & Mix'!D10/'Volume & Mix'!D13 -> 0.63636364 | E14: ='Volume & Mix'!E10/'Volume & Mix'!E13 -> 0.63636364 | F14: ='Volume & Mix'!F10/'Volume & Mix'!F13 -> 0.63636364 | H14: Dominant book share — 105d tenor + 50% mix
A15: Term Extension share | B15: ='Volume & Mix'!B11/'Volume & Mix'!B13 -> 0.21818182 | C15: ='Volume & Mix'!C11/'Volume & Mix'!C13 -> 0.21818182 | D15: ='Volume & Mix'!D11/'Volume & Mix'!D13 -> 0.21818182 | E15: ='Volume & Mix'!E11/'Volume & Mix'!E13 -> 0.21818182 | F15: ='Volume & Mix'!F11/'Volume & Mix'!F13 -> 0.21818182 | H15: 180d distressed tenor

Sheet Risk
A1: Risk Layer · PD / LGD / EAD by Track
A2: Basel III IRB Foundation framework. EL = PD × LGD × EAD × book. Sources: Moody's UAE Banking 2026, CBUAE FSR 2025 §3.4, Basel III IRB.
A4: Parameter | B4: Pay-30 | C4: BNPL | D4: Term Extension | E4: Stress (1.5× PD) | F4: Source / Note
A5: PD (% p.a.) | B5: 2 | C5: 4 | D5: 10 | E5: =B5*1.5 -> 3 | F5: Stress = base PD × 1.5 (CBUAE 2020 COVID-19 downturn template)
A6: LGD (%) | B6: 35 | C6: 45 | D6: 65 | E6: (unchanged) | F6: LGD held flat under PD stress; downturn-LGD test in Scenarios
A7: EAD (% of book) | B7: 100 | C7: 100 | D7: 100 | E7: (unchanged) | F7: Phase 2: introduce CCF-based EAD if a revolving facility variant is launched
A9: Net loss rate (% of book) | B9: =B5*B6/100*B7/100 -> 0.7 | C9: =C5*C6/100*C7/100 -> 1.8 | D9: =D5*D6/100*D7/100 -> 6.5 | E9: see stress block below | F9: = PD×LGD×EAD (annualised, % of avg book)
A10: Stressed net loss rate (1.5× PD) | B10: =E5*B6/100*B7/100 -> 1.05 | C10: =C5*1.5*C6/100*C7/100 -> 2.7 | D10: =D5*1.5*D6/100*D7/100 -> 9.75 | F10: Stress = PD × 1.5; LGD/EAD held

Sheet Track A · Pay-30
A1: Track A · Pay-30 (single-bullet)
A2: Single-bullet 30-day pay. Invoice acts as collateral. Lowest default; lowest yield.
A4: Line | B4: Y1 | C4: Y2 | D4: Y3 | E4: Y4 | F4: Y5 | H4: Formula
A5: Avg book | B5: ='Volume & Mix'!B9 -> 7.3972603 | C5: ='Volume & Mix'!C9 -> 44.383562 | D5: ='Volume & Mix'!D9 -> 118.35616 | E5: ='Volume & Mix'!E9 -> 236.71233 | F5: ='Volume & Mix'!F9 -> 384.65753 | H5: from 'Volume & Mix'
A6: Gross yield (% APR) | B6: =fee_pay30_mo*12 -> 15.6 | C6: =fee_pay30_mo*12 -> 15.6 | D6: =fee_pay30_mo*12 -> 15.6 | E6: =fee_pay30_mo*12 -> 15.6 | F6: =fee_pay30_mo*12 -> 15.6 | H6: fee_pay30_mo × 12 = APR
A7: Gross interest income (AED M) | B7: =B5*B6/100 -> 1.1539726 | C7: =C5*C6/100 -> 6.9238356 | D7: =D5*D6/100 -> 18.463562 | E7: =E5*E6/100 -> 36.927123 | F7: =F5*F6/100 -> 60.006575 | H7: book × yield
A9: Cost of funds (% APR) | B9: =cof_apr -> 6.5 | C9: =cof_apr -> 6.5 | D9: =cof_apr -> 6.5 | E9: =cof_apr -> 6.5 | F9: =cof_apr -> 6.5
A10: Funding cost (AED M) | B10: =B5*B9/100 -> 0.48082192 | C10: =C5*C9/100 -> 2.8849315 | D10: =D5*D9/100 -> 7.6931507 | E10: =E5*E9/100 -> 15.386301 | F10: =F5*F9/100 -> 25.00274 | H10: book × COF
A12: NIM (AED M) | B12: =B7-B10 -> 0.67315068 | C12: =C7-C10 -> 4.0389041 | D12: =D7-D10 -> 10.770411 | E12: =E7-E10 -> 21.540822 | F12: =F7-F10 -> 35.003836 | H12: gross - funding
A14: PD (% APR) — pd_pay30 | B14: =pd_pay30 -> 2 | C14: =pd_pay30 -> 2 | D14: =pd_pay30 -> 2 | E14: =pd_pay30 -> 2 | F14: =pd_pay30 -> 2 | H14: Probability of default — Risk Layer sheet
A15: LGD (%) — lgd_pay30 | B15: =lgd_pay30 -> 35 | C15: =lgd_pay30 -> 35 | D15: =lgd_pay30 -> 35 | E15: =lgd_pay30 -> 35 | F15: =lgd_pay30 -> 35 | H15: Loss given default — collateral-implied
A16: Net loss rate (% of book) | B16: =B14*B15/100*ead_pay30/100 -> 0.7 | C16: =C14*C15/100*ead_pay30/100 -> 0.7 | D16: =D14*D15/100*ead_pay30/100 -> 0.7 | E16: =E14*E15/100*ead_pay30/100 -> 0.7 | F16: =F14*F15/100*ead_pay30/100 -> 0.7 | H16: PD × LGD × EAD
A17: Loss provision (AED M) | B17: =B5*B16/100 -> 0.051780822 | C17: =C5*C16/100 -> 0.31068493 | D17: =D5*D16/100 -> 0.82849315 | E17: =E5*E16/100 -> 1.6569863 | F17: =F5*F16/100 -> 2.6926027 | H17: book × net loss rate
A19: Risk-adj margin (AED M) | B19: =B12-B17 -> 0.62136986 | C19: =C12-C17 -> 3.7282192 | D19: =D12-D17 -> 9.9419178 | E19: =E12-E17 -> 19.883836 | F19: =F12-F17 -> 32.311233 | H19: NIM - losses
A21: OpEx % of book (Y1–Y5 ramp) | B21: =opex_pct*opex_y1_mult -> 4.008 | C21: =opex_pct*opex_y2_mult -> 3 | D21: =opex_pct*opex_y3_mult -> 2.4 | E21: =opex_pct*opex_y4_mult -> 2.28 | F21: =opex_pct*opex_y5_mult -> 2.208 | H21: ramps to mature in Y3
A22: OpEx (AED M) | B22: =B5*B21/100 -> 0.29648219 | C22: =C5*C21/100 -> 1.3315068 | D22: =D5*D21/100 -> 2.8405479 | E22: =E5*E21/100 -> 5.3970411 | F22: =F5*F21/100 -> 8.4932384 | H22: book × opex%
A24: Net contribution (AED M) | B24: =B19-B22 -> 0.32488767 | C24: =C19-C22 -> 2.3967123 | D24: =D19-D22 -> 7.1013699 | E24: =E19-E22 -> 14.486795 | F24: =F19-F22 -> 23.817995 | H24: RAM - OpEx
A25: ROA (% of avg book) | B25: =B24/B5*100 -> 4.392 | C25: =C24/C5*100 -> 5.4 | D25: =D24/D5*100 -> 6 | E25: =E24/E5*100 -> 6.12 | F25: =F24/F5*100 -> 6.192 | H25: net contrib / book
A27: Equity allocated (AED M) | B27: =B5*equity_pct/100 -> 1.0356164 | C27: =C5*equity_pct/100 -> 6.2136986 | D27: =D5*equity_pct/100 -> 16.569863 | E27: =E5*equity_pct/100 -> 33.139726 | F27: =F5*equity_pct/100 -> 53.852055 | H27: book × equity_pct
A28: RAROC (% on equity) | B28: =IF(B27>0,B24/B27*100,0) -> 31.371429 | C28: =IF(C27>0,C24/C27*100,0) -> 38.571429 | D28: =IF(D27>0,D24/D27*100,0) -> 42.857143 | E28: =IF(E27>0,E24/E27*100,0) -> 43.714286 | F28: =IF(F27>0,F24/F27*100,0) -> 44.228571 | H28: net contrib / equity

Sheet Track B · BNPL
A1: Track B · BNPL (60/90/120/180 blended)
A2: Multi-installment over 60–180 days. Higher exposure → higher default. Yield priced ~12.5% above Pay-30.
A4: Line | B4: Y1 | C4: Y2 | D4: Y3 | E4: Y4 | F4: Y5 | H4: Formula
A5: Avg book | B5: ='Volume & Mix'!B10 -> 32.363014 | C5: ='Volume & Mix'!C10 -> 194.17808 | D5: ='Volume & Mix'!D10 -> 517.80822 | E5: ='Volume & Mix'!E10 -> 1035.6164 | F5: ='Volume & Mix'!F10 -> 1682.8767 | H5: from 'Volume & Mix'
A6: Gross yield (% APR) | B6: =fee_bnpl_mo*12 -> 18 | C6: =fee_bnpl_mo*12 -> 18 | D6: =fee_bnpl_mo*12 -> 18 | E6: =fee_bnpl_mo*12 -> 18 | F6: =fee_bnpl_mo*12 -> 18 | H6: fee_bnpl_mo × 12 = APR
A7: Gross interest income (AED M) | B7: =B5*B6/100 -> 5.8253425 | C7: =C5*C6/100 -> 34.952055 | D7: =D5*D6/100 -> 93.205479 | E7: =E5*E6/100 -> 186.41096 | F7: =F5*F6/100 -> 302.91781 | H7: book × yield
A9: Cost of funds (% APR) | B9: =cof_apr -> 6.5 | C9: =cof_apr -> 6.5 | D9: =cof_apr -> 6.5 | E9: =cof_apr -> 6.5 | F9: =cof_apr -> 6.5
A10: Funding cost (AED M) | B10: =B5*B9/100 -> 2.1035959 | C10: =C5*C9/100 -> 12.621575 | D10: =D5*D9/100 -> 33.657534 | E10: =E5*E9/100 -> 67.315068 | F10: =F5*F9/100 -> 109.38699 | H10: book × COF
A12: NIM (AED M) | B12: =B7-B10 -> 3.7217466 | C12: =C7-C10 -> 22.330479 | D12: =D7-D10 -> 59.547945 | E12: =E7-E10 -> 119.09589 | F12: =F7-F10 -> 193.53082 | H12: gross - funding
A14: PD (% APR) — pd_bnpl | B14: =pd_bnpl -> 4 | C14: =pd_bnpl -> 4 | D14: =pd_bnpl -> 4 | E14: =pd_bnpl -> 4 | F14: =pd_bnpl -> 4 | H14: Probability of default — Risk Layer sheet
A15: LGD (%) — lgd_bnpl | B15: =lgd_bnpl -> 45 | C15: =lgd_bnpl -> 45 | D15: =lgd_bnpl -> 45 | E15: =lgd_bnpl -> 45 | F15: =lgd_bnpl -> 45 | H15: Loss given default — multi-installment
A16: Net loss rate (% of book) | B16: =B14*B15/100*ead_bnpl/100 -> 1.8 | C16: =C14*C15/100*ead_bnpl/100 -> 1.8 | D16: =D14*D15/100*ead_bnpl/100 -> 1.8 | E16: =E14*E15/100*ead_bnpl/100 -> 1.8 | F16: =F14*F15/100*ead_bnpl/100 -> 1.8 | H16: PD × LGD × EAD
A17: Loss provision (AED M) | B17: =B5*B16/100 -> 0.58253425 | C17: =C5*C16/100 -> 3.4952055 | D17: =D5*D16/100 -> 9.3205479 | E17: =E5*E16/100 -> 18.641096 | F17: =F5*F16/100 -> 30.291781 | H17: book × net loss rate
A19: Risk-adj margin (AED M) | B19: =B12-B17 -> 3.1392123 | C19: =C12-C17 -> 18.835274 | D19: =D12-D17 -> 50.227397 | E19: =E12-E17 -> 100.45479 | F19: =F12-F17 -> 163.23904 | H19: NIM - losses
A21: OpEx % of book (Y1–Y5 ramp) | B21: =opex_pct*opex_y1_mult -> 4.008 | C21: =opex_pct*opex_y2_mult -> 3 | D21: =opex_pct*opex_y3_mult -> 2.4 | E21: =opex_pct*opex_y4_mult -> 2.28 | F21: =opex_pct*opex_y5_mult -> 2.208 | H21: ramps to mature in Y3
A22: OpEx (AED M) | B22: =B5*B21/100 -> 1.2971096 | C22: =C5*C21/100 -> 5.8253425 | D22: =D5*D21/100 -> 12.427397 | E22: =E5*E21/100 -> 23.612055 | F22: =F5*F21/100 -> 37.157918 | H22: book × opex%
A24: Net contribution (AED M) | B24: =B19-B22 -> 1.8421027 | C24: =C19-C22 -> 13.009932 | D24: =D19-D22 -> 37.8 | E24: =E19-E22 -> 76.84274 | F24: =F19-F22 -> 126.08112 | H24: RAM - OpEx
A25: ROA (% of avg book) | B25: =B24/B5*100 -> 5.692 | C25: =C24/C5*100 -> 6.7 | D25: =D24/D5*100 -> 7.3 | E25: =E24/E5*100 -> 7.42 | F25: =F24/F5*100 -> 7.492 | H25: net contrib / book
A27: Equity allocated (AED M) | B27: =B5*equity_pct/100 -> 4.5308219 | C27: =C5*equity_pct/100 -> 27.184932 | D27: =D5*equity_pct/100 -> 72.493151 | E27: =E5*equity_pct/100 -> 144.9863 | F27: =F5*equity_pct/100 -> 235.60274 | H27: book × equity_pct
A28: RAROC (% on equity) | B28: =IF(B27>0,B24/B27*100,0) -> 40.657143 | C28: =IF(C27>0,C24/C27*100,0) -> 47.857143 | D28: =IF(D27>0,D24/D27*100,0) -> 52.142857 | E28: =IF(E27>0,E24/E27*100,0) -> 53 | F28: =IF(F27>0,F24/F27*100,0) -> 53.514286 | H28: net contrib / equity

Sheet Track C · Extension
A1: Track C · Term Extension (6-mo restructure)
A2: Workout product for Pay-30/BNPL non-payers. APR-priced. Distressed cohort: highest default; recovery lower.
A4: Line | B4: Y1 | C4: Y2 | D4: Y3 | E4: Y4 | F4: Y5 | H4: Formula
A5: Avg book | B5: ='Volume & Mix'!B11 -> 11.09589 | C5: ='Volume & Mix'!C11 -> 66.575342 | D5: ='Volume & Mix'!D11 -> 177.53425 | E5: ='Volume & Mix'!E11 -> 355.06849 | F5: ='Volume & Mix'!F11 -> 576.9863 | H5: from 'Volume & Mix'
A6: Gross yield (% APR) | B6: =fee_ext_apr -> 16 | C6: =fee_ext_apr -> 16 | D6: =fee_ext_apr -> 16 | E6: =fee_ext_apr -> 16 | F6: =fee_ext_apr -> 16 | H6: fee_ext_apr (direct APR)
A7: Gross interest income (AED M) | B7: =B5*B6/100 -> 1.7753425 | C7: =C5*C6/100 -> 10.652055 | D7: =D5*D6/100 -> 28.405479 | E7: =E5*E6/100 -> 56.810959 | F7: =F5*F6/100 -> 92.317808 | H7: book × yield
A9: Cost of funds (% APR) | B9: =cof_apr -> 6.5 | C9: =cof_apr -> 6.5 | D9: =cof_apr -> 6.5 | E9: =cof_apr -> 6.5 | F9: =cof_apr -> 6.5
A10: Funding cost (AED M) | B10: =B5*B9/100 -> 0.72123288 | C10: =C5*C9/100 -> 4.3273973 | D10: =D5*D9/100 -> 11.539726 | E10: =E5*E9/100 -> 23.079452 | F10: =F5*F9/100 -> 37.50411 | H10: book × COF
A12: NIM (AED M) | B12: =B7-B10 -> 1.0541096 | C12: =C7-C10 -> 6.3246575 | D12: =D7-D10 -> 16.865753 | E12: =E7-E10 -> 33.731507 | F12: =F7-F10 -> 54.813699 | H12: gross - funding
A14: PD (% APR) — pd_ext | B14: =pd_ext -> 10 | C14: =pd_ext -> 10 | D14: =pd_ext -> 10 | E14: =pd_ext -> 10 | F14: =pd_ext -> 10 | H14: Probability of default — Risk Layer sheet
A15: LGD (%) — lgd_ext | B15: =lgd_ext -> 65 | C15: =lgd_ext -> 65 | D15: =lgd_ext -> 65 | E15: =lgd_ext -> 65 | F15: =lgd_ext -> 65 | H15: Loss given default — workout/distressed
A16: Net loss rate (% of book) | B16: =B14*B15/100*ead_ext/100 -> 6.5 | C16: =C14*C15/100*ead_ext/100 -> 6.5 | D16: =D14*D15/100*ead_ext/100 -> 6.5 | E16: =E14*E15/100*ead_ext/100 -> 6.5 | F16: =F14*F15/100*ead_ext/100 -> 6.5 | H16: PD × LGD × EAD
A17: Loss provision (AED M) | B17: =B5*B16/100 -> 0.72123288 | C17: =C5*C16/100 -> 4.3273973 | D17: =D5*D16/100 -> 11.539726 | E17: =E5*E16/100 -> 23.079452 | F17: =F5*F16/100 -> 37.50411 | H17: book × net loss rate
A19: Risk-adj margin (AED M) | B19: =B12-B17 -> 0.33287671 | C19: =C12-C17 -> 1.9972603 | D19: =D12-D17 -> 5.3260274 | E19: =E12-E17 -> 10.652055 | F19: =F12-F17 -> 17.309589 | H19: NIM - losses
A21: OpEx % of book (Y1–Y5 ramp) | B21: =opex_pct*opex_y1_mult -> 4.008 | C21: =opex_pct*opex_y2_mult -> 3 | D21: =opex_pct*opex_y3_mult -> 2.4 | E21: =opex_pct*opex_y4_mult -> 2.28 | F21: =opex_pct*opex_y5_mult -> 2.208 | H21: ramps to mature in Y3
A22: OpEx (AED M) | B22: =B5*B21/100 -> 0.44472329 | C22: =C5*C21/100 -> 1.9972603 | D22: =D5*D21/100 -> 4.2608219 | E22: =E5*E21/100 -> 8.0955616 | F22: =F5*F21/100 -> 12.739858 | H22: book × opex%
A24: Net contribution (AED M) | B24: =B19-B22 -> -0.11184658 | C24: =C19-C22 -> 0 | D24: =D19-D22 -> 1.0652055 | E24: =E19-E22 -> 2.5564932 | F24: =F19-F22 -> 4.5697315 | H24: RAM - OpEx
A25: ROA (% of avg book) | B25: =B24/B5*100 -> -1.008 | C25: =C24/C5*100 -> 0 | D25: =D24/D5*100 -> 0.6 | E25: =E24/E5*100 -> 0.72 | F25: =F24/F5*100 -> 0.792 | H25: net contrib / book
A27: Equity allocated (AED M) | B27: =B5*equity_pct/100 -> 1.5534247 | C27: =C5*equity_pct/100 -> 9.3205479 | D27: =D5*equity_pct/100 -> 24.854795 | E27: =E5*equity_pct/100 -> 49.709589 | F27: =F5*equity_pct/100 -> 80.778082 | H27: book × equity_pct
A28: RAROC (% on equity) | B28: =IF(B27>0,B24/B27*100,0) -> -7.2 | C28: =IF(C27>0,C24/C27*100,0) -> 0 | D28: =IF(D27>0,D24/D27*100,0) -> 4.2857143 | E28: =IF(E27>0,E24/E27*100,0) -> 5.1428571 | F28: =IF(F27>0,F24/F27*100,0) -> 5.6571429 | H28: net contrib / equity

Sheet Combined P&L
A1: Combined Smart Invoice P&L
A2: Track A + Track B + Track C, five-year roll-up (Y1–Y5)
A4: Line (AED M) | B4: Y1 | C4: Y2 | D4: Y3 | E4: Y4 | F4: Y5
A5: Avg book | B5: ='Track A · Pay-30'!B5+'Track B · BNPL'!B5+'Track C · Extension'!B5 -> 50.856164 | C5: ='Track A · Pay-30'!C5+'Track B · BNPL'!C5+'Track C · Extension'!C5 -> 305.13699 | D5: ='Track A · Pay-30'!D5+'Track B · BNPL'!D5+'Track C · Extension'!D5 -> 813.69863 | E5: ='Track A · Pay-30'!E5+'Track B · BNPL'!E5+'Track C · Extension'!E5 -> 1627.3973 | F5: ='Track A · Pay-30'!F5+'Track B · BNPL'!F5+'Track C · Extension'!F5 -> 2644.5205
A6: Gross interest income | B6: ='Track A · Pay-30'!B7+'Track B · BNPL'!B7+'Track C · Extension'!B7 -> 8.7546575 | C6: ='Track A · Pay-30'!C7+'Track B · BNPL'!C7+'Track C · Extension'!C7 -> 52.527945 | D6: ='Track A · Pay-30'!D7+'Track B · BNPL'!D7+'Track C · Extension'!D7 -> 140.07452 | E6: ='Track A · Pay-30'!E7+'Track B · BNPL'!E7+'Track C · Extension'!E7 -> 280.14904 | F6: ='Track A · Pay-30'!F7+'Track B · BNPL'!F7+'Track C · Extension'!F7 -> 455.24219
A7: Funding cost | B7: ='Track A · Pay-30'!B10+'Track B · BNPL'!B10+'Track C · Extension'!B10 -> 3.3056507 | C7: ='Track A · Pay-30'!C10+'Track B · BNPL'!C10+'Track C · Extension'!C10 -> 19.833904 | D7: ='Track A · Pay-30'!D10+'Track B · BNPL'!D10+'Track C · Extension'!D10 -> 52.890411 | E7: ='Track A · Pay-30'!E10+'Track B · BNPL'!E10+'Track C · Extension'!E10 -> 105.78082 | F7: ='Track A · Pay-30'!F10+'Track B · BNPL'!F10+'Track C · Extension'!F10 -> 171.89384
A8: NIM | B8: ='Track A · Pay-30'!B12+'Track B · BNPL'!B12+'Track C · Extension'!B12 -> 5.4490068 | C8: ='Track A · Pay-30'!C12+'Track B · BNPL'!C12+'Track C · Extension'!C12 -> 32.694041 | D8: ='Track A · Pay-30'!D12+'Track B · BNPL'!D12+'Track C · Extension'!D12 -> 87.18411 | E8: ='Track A · Pay-30'!E12+'Track B · BNPL'!E12+'Track C · Extension'!E12 -> 174.36822 | F8: ='Track A · Pay-30'!F12+'Track B · BNPL'!F12+'Track C · Extension'!F12 -> 283.34836
A9: Loss provision | B9: ='Track A · Pay-30'!B17+'Track B · BNPL'!B17+'Track C · Extension'!B17 -> 1.3555479 | C9: ='Track A · Pay-30'!C17+'Track B · BNPL'!C17+'Track C · Extension'!C17 -> 8.1332877 | D9: ='Track A · Pay-30'!D17+'Track B · BNPL'!D17+'Track C · Extension'!D17 -> 21.688767 | E9: ='Track A · Pay-30'!E17+'Track B · BNPL'!E17+'Track C · Extension'!E17 -> 43.377534 | F9: ='Track A · Pay-30'!F17+'Track B · BNPL'!F17+'Track C · Extension'!F17 -> 70.488493
A10: Risk-adj margin | B10: ='Track A · Pay-30'!B19+'Track B · BNPL'!B19+'Track C · Extension'!B19 -> 4.0934589 | C10: ='Track A · Pay-30'!C19+'Track B · BNPL'!C19+'Track C · Extension'!C19 -> 24.560753 | D10: ='Track A · Pay-30'!D19+'Track B · BNPL'!D19+'Track C · Extension'!D19 -> 65.495342 | E10: ='Track A · Pay-30'!E19+'Track B · BNPL'!E19+'Track C · Extension'!E19 -> 130.99068 | F10: ='Track A · Pay-30'!F19+'Track B · BNPL'!F19+'Track C · Extension'!F19 -> 212.85986
A11: OpEx | B11: ='Track A · Pay-30'!B22+'Track B · BNPL'!B22+'Track C · Extension'!B22 -> 2.0383151 | C11: ='Track A · Pay-30'!C22+'Track B · BNPL'!C22+'Track C · Extension'!C22 -> 9.1541096 | D11: ='Track A · Pay-30'!D22+'Track B · BNPL'!D22+'Track C · Extension'!D22 -> 19.528767 | E11: ='Track A · Pay-30'!E22+'Track B · BNPL'!E22+'Track C · Extension'!E22 -> 37.104658 | F11: ='Track A · Pay-30'!F22+'Track B · BNPL'!F22+'Track C · Extension'!F22 -> 58.391014
A12: Net contribution | B12: ='Track A · Pay-30'!B24+'Track B · BNPL'!B24+'Track C · Extension'!B24 -> 2.0551438 | C12: ='Track A · Pay-30'!C24+'Track B · BNPL'!C24+'Track C · Extension'!C24 -> 15.406644 | D12: ='Track A · Pay-30'!D24+'Track B · BNPL'!D24+'Track C · Extension'!D24 -> 45.966575 | E12: ='Track A · Pay-30'!E24+'Track B · BNPL'!E24+'Track C · Extension'!E24 -> 93.886027 | F12: ='Track A · Pay-30'!F24+'Track B · BNPL'!F24+'Track C · Extension'!F24 -> 154.46885
A13: Equity | B13: ='Track A · Pay-30'!B27+'Track B · BNPL'!B27+'Track C · Extension'!B27 -> 7.119863 | C13: ='Track A · Pay-30'!C27+'Track B · BNPL'!C27+'Track C · Extension'!C27 -> 42.719178 | D13: ='Track A · Pay-30'!D27+'Track B · BNPL'!D27+'Track C · Extension'!D27 -> 113.91781 | E13: ='Track A · Pay-30'!E27+'Track B · BNPL'!E27+'Track C · Extension'!E27 -> 227.83562 | F13: ='Track A · Pay-30'!F27+'Track B · BNPL'!F27+'Track C · Extension'!F27 -> 370.23288
A15: Ratios
A16: NIM (% of book) | B16: =B8/B5*100 -> 10.714545 | C16: =C8/C5*100 -> 10.714545 | D16: =D8/D5*100 -> 10.714545 | E16: =E8/E5*100 -> 10.714545 | F16: =F8/F5*100 -> 10.714545
A17: Loss rate (% of book) | B17: =B9/B5*100 -> 2.6654545 | C17: =C9/C5*100 -> 2.6654545 | D17: =D9/D5*100 -> 2.6654545 | E17: =E9/E5*100 -> 2.6654545 | F17: =F9/F5*100 -> 2.6654545
A18: OpEx (% of book) | B18: =B11/B5*100 -> 4.008 | C18: =C11/C5*100 -> 3 | D18: =D11/D5*100 -> 2.4 | E18: =E11/E5*100 -> 2.28 | F18: =F11/F5*100 -> 2.208
A19: Net margin (% of revenue) | B19: =IF(B6>0,B12/B6*100,0) -> 23.474863 | C19: =IF(C6>0,C12/C6*100,0) -> 29.330376 | D19: =IF(D6>0,D12/D6*100,0) -> 32.815801 | E19: =IF(E6>0,E12/E6*100,0) -> 33.512886 | F19: =IF(F6>0,F12/F6*100,0) -> 33.931136
A20: ROA (% of avg book) | B20: =B12/B5*100 -> 4.0410909 | C20: =C12/C5*100 -> 5.0490909 | D20: =D12/D5*100 -> 5.6490909 | E20: =E12/E5*100 -> 5.7690909 | F20: =F12/F5*100 -> 5.8410909
A21: RAROC (% on equity) | B21: =IF(B13>0,B12/B13*100,0) -> 28.864935 | C21: =IF(C13>0,C12/C13*100,0) -> 36.064935 | D21: =IF(D13>0,D12/D13*100,0) -> 40.350649 | E21: =IF(E13>0,E12/E13*100,0) -> 41.207792 | F21: =IF(F13>0,F12/F13*100,0) -> 41.722078
A23: Reconciliation to Reported Earnings
A24: Walks operating Net contribution to post-tax return on equity. Adds CAC, compliance overhead, write-off true-up, and UAE CIT (9%).
A26: Operating Net contribution (from row 12) | B26: =B12 -> 2.0551438 | C26: =C12 -> 15.406644 | D26: =D12 -> 45.966575 | E26: =E12 -> 93.886027 | F26: =F12 -> 154.46885
A28: (−) Customer acquisition cost | B28: =-'Volume & Mix'!B5*0.005 -> -1.25 | C28: =-'Volume & Mix'!C5*0.0035 -> -5.25 | D28: =-'Volume & Mix'!D5*0.002 -> -8 | E28: =-'Volume & Mix'!E5*0.0015 -> -12 | F28: =-'Volume & Mix'!F5*0.0012 -> -15.6
A29: (−) Compliance & regulatory overhead | B29: -3 | C29: -5 | D29: -7 | E29: -10 | F29: -12
A30: (−) Bad-debt write-off true-up | B30: =-B5*0.0025 -> -0.12714041 | C30: =-C5*0.0025 -> -0.76284247 | D30: =-D5*0.0025 -> -2.0342466 | E30: =-E5*0.0025 -> -4.0684932 | F30: =-F5*0.0025 -> -6.6113014
A32: Pre-tax income | B32: =SUM(B26:B30) -> -2.3219966 | C32: =SUM(C26:C30) -> 4.3938014 | D32: =SUM(D26:D30) -> 28.932329 | E32: =SUM(E26:E30) -> 67.817534 | F32: =SUM(F26:F30) -> 120.25755
A33: (−) UAE corporate tax (9%) | B33: =-MAX(0,B32)*0.09 -> 0 | C33: =-MAX(0,C32)*0.09 -> -0.39544212 | D33: =-MAX(0,D32)*0.09 -> -2.6039096 | E33: =-MAX(0,E32)*0.09 -> -6.1035781 | F33: =-MAX(0,F32)*0.09 -> -10.823179
A35: Net income to equity | B35: =B32+B33 -> -2.3219966 | C35: =C32+C33 -> 3.9983592 | D35: =D32+D33 -> 26.328419 | E35: =E32+E33 -> 61.713956 | F35: =F32+F33 -> 109.43437
A37: Post-tax ROA (% of avg book) | B37: =B35/B5*100 -> -4.5658114 | C37: =C35/C5*100 -> 1.3103489 | D37: =D35/D5*100 -> 3.2356475 | E37: =E35/E5*100 -> 3.7921875 | F37: =F35/F5*100 -> 4.1381554
A38: Post-tax RAROC (% on equity) | B38: =IF(B13>0,B35/B13*100,0) -> -32.612939 | C38: =IF(C13>0,C35/C13*100,0) -> 9.3596352 | D38: =IF(D13>0,D35/D13*100,0) -> 23.111768 | E38: =IF(E13>0,E35/E13*100,0) -> 27.087054 | F38: =IF(F13>0,F35/F13*100,0) -> 29.558253

Sheet Unit Economics
A1: Unit Economics — per AED 100k of Invoice Face Value
A2: Per-invoice contribution by track. Useful for pricing-committee debates.
A4: Line (AED per 100k) | B4: Pay-30 | C4: BNPL | D4: Extension
A5: Invoice face | B5: =100000 -> 100000 | C5: =100000 -> 100000 | D5: =100000 -> 100000
A6: Advanced principal | B6: =B5*advance_rate/100 -> 90000 | C6: =B5*advance_rate/100 -> 90000 | D6: =B5*advance_rate/100 -> 90000
A7: Tenor (days) | B7: =tenor_pay30 -> 30 | C7: =tenor_bnpl -> 105 | D7: =tenor_ext -> 180
A8: Yield (annual %) | B8: =fee_pay30_mo*12 -> 15.6 | C8: =fee_bnpl_mo*12 -> 18 | D8: =fee_ext_apr -> 16
A9: Gross fee earned | B9: =B6*B8/100*B7/365 -> 1153.9726 | C9: =C6*C8/100*C7/365 -> 4660.274 | D9: =D6*D8/100*D7/365 -> 7101.3699
A10: Funding cost | B10: =B6*cof_apr/100*B7/365 -> 480.82192 | C10: =C6*cof_apr/100*C7/365 -> 1682.8767 | D10: =D6*cof_apr/100*D7/365 -> 2884.9315
A11: NIM | B11: =B9-B10 -> 673.15068 | C11: =C9-C10 -> 2977.3973 | D11: =D9-D10 -> 4216.4384
A12: Expected loss | B12: =B6*pd_pay30/100*lgd_pay30/100*ead_pay30/100*B7/365 -> 51.780822 | C12: =C6*pd_bnpl/100*lgd_bnpl/100*ead_bnpl/100*C7/365 -> 466.0274 | D12: =D6*pd_ext/100*lgd_ext/100*ead_ext/100*D7/365 -> 2884.9315
A13: Risk-adj margin | B13: =B11-B12 -> 621.36986 | C13: =C11-C12 -> 2511.3699 | D13: =D11-D12 -> 1331.5068
A14: OpEx (mature, % of book) | B14: =B6*opex_pct/100*B7/365 -> 177.53425 | C14: =C6*opex_pct/100*C7/365 -> 621.36986 | D14: =D6*opex_pct/100*D7/365 -> 1065.2055
A15: Net contribution per invoice | B15: =B13-B14 -> 443.83562 | C15: =C13-C14 -> 1890 | D15: =D13-D14 -> 266.30137
A16: Net contribution as % of face | B16: =B15/B5*100 -> 0.44383562 | C16: =C15/C5*100 -> 1.89 | D16: =D15/D5*100 -> 0.26630137

Sheet Sensitivity
A1: Sensitivity · Y3 Net Contribution (AED M) vs PD Multiplier × Cost of Funds
A2: Holds all else constant. Useful for stress-test discussions with risk committee.
J3: PD mult → | K3: 0.6 | L3: 0.8 | M3: 1 | N3: 1.2 | O3: 1.5 | P3: 1.8 | Q3: 2.2
A4: PD × → / COF ↓ | B4: 0.6× PD | C4: 0.8× PD | D4: 1.0× PD | E4: 1.2× PD | F4: 1.5× PD | G4: 1.8× PD | H4: 2.2× PD | J4: COF ↓
A5: COF 5.5% | B5: =(disb_y3*advance_rate/100*tenor_pay30/365*mix_pay30/100)*(fee_pay30_mo*12/100-$J5-pd_pay30*K$3*lgd_pay30/100*ead_pay30/100/100-opex_pct*opex_y3_mult/100)+(disb_y3*advance_rate/100*tenor_bnpl/365*mix_bnpl/100)*(fee_bnpl_mo*12/100-$J5-pd_bnpl*K$3*lgd_bnpl/100*ead_bnpl/100/100-opex_pct*opex_y3_mult/100)+(disb_y3*advance_rate/100*tenor_ext/365*mix_ext/100)*(fee_ext_apr/100-$J5-pd_ext*K$3*lgd_ext/100*ead_ext/100/100-opex_pct*opex_y3_mult/100) -> 62.779068 | C5: =(disb_y3*advance_rate/100*tenor_pay30/365*mix_pay30/100)*(fee_pay30_mo*12/100-$J5-pd_pay30*L$3*lgd_pay30/100*ead_pay30/100/100-opex_pct*opex_y3_mult/100)+(disb_y3*advance_rate/100*tenor_bnpl/365*mix_bnpl/100)*(fee_bnpl_mo*12/100-$J5-pd_bnpl*L$3*lgd_bnpl/100*ead_bnpl/100/100-opex_pct*opex_y3_mult/100)+(disb_y3*advance_rate/100*tenor_ext/365*mix_ext/100)*(fee_ext_apr/100-$J5-pd_ext*L$3*lgd_ext/100*ead_ext/100/100-opex_pct*opex_y3_mult/100) -> 58.441315 | D5: =(disb_y3*advance_rate/100*tenor_pay30/365*mix_pay30/100)*(fee_pay30_mo*12/100-$J5-pd_pay30*M$3*lgd_pay30/100*ead_pay30/100/100-opex_pct*opex_y3_mult/100)+(disb_y3*advance_rate/100*tenor_bnpl/365*mix_bnpl/100)*(fee_bnpl_mo*12/100-$J5-pd_bnpl*M$3*lgd_bnpl/100*ead_bnpl/100/100-opex_pct*opex_y3_mult/100)+(disb_y3*advance_rate/100*tenor_ext/365*mix_ext/100)*(fee_ext_apr/100-$J5-pd_ext*M$3*lgd_ext/100*ead_ext/100/100-opex_pct*opex_y3_mult/100) -> 54.103562 | E5: =(disb_y3*advance_rate/100*tenor_pay30/365*mix_pay30/100)*(fee_pay30_mo*12/100-$J5-pd_pay30*N$3*lgd_pay30/100*ead_pay30/100/100-opex_pct*opex_y3_mult/100)+(disb_y3*advance_rate/100*tenor_bnpl/365*mix_bnpl/100)*(fee_bnpl_mo*12/100-$J5-pd_bnpl*N$3*lgd_bnpl/100*ead_bnpl/100/100-opex_pct*opex_y3_mult/100)+(disb_y3*advance_rate/100*tenor_ext/365*mix_ext/100)*(fee_ext_apr/100-$J5-pd_ext*N$3*lgd_ext/100*ead_ext/100/100-opex_pct*opex_y3_mult/100) -> 49.765808 | F5: =(disb_y3*advance_rate/100*tenor_pay30/365*mix_pay30/100)*(fee_pay30_mo*12/100-$J5-pd_pay30*O$3*lgd_pay30/100*ead_pay30/100/100-opex_pct*opex_y3_mult/100)+(disb_y3*advance_rate/100*tenor_bnpl/365*mix_bnpl/100)*(fee_bnpl_mo*12/100-$J5-pd_bnpl*O$3*lgd_bnpl/100*ead_bnpl/100/100-opex_pct*opex_y3_mult/100)+(disb_y3*advance_rate/100*tenor_ext/365*mix_ext/100)*(fee_ext_apr/100-$J5-pd_ext*O$3*lgd_ext/100*ead_ext/100/100-opex_pct*opex_y3_mult/100) -> 43.259178 | G5: =(disb_y3*advance_rate/100*tenor_pay30/365*mix_pay30/100)*(fee_pay30_mo*12/100-$J5-pd_pay30*P$3*lgd_pay30/100*ead_pay30/100/100-opex_pct*opex_y3_mult/100)+(disb_y3*advance_rate/100*tenor_bnpl/365*mix_bnpl/100)*(fee_bnpl_mo*12/100-$J5-pd_bnpl*P$3*lgd_bnpl/100*ead_bnpl/100/100-opex_pct*opex_y3_mult/100)+(disb_y3*advance_rate/100*tenor_ext/365*mix_ext/100)*(fee_ext_apr/100-$J5-pd_ext*P$3*lgd_ext/100*ead_ext/100/100-opex_pct*opex_y3_mult/100) -> 36.752548 | H5: =(disb_y3*advance_rate/100*tenor_pay30/365*mix_pay30/100)*(fee_pay30_mo*12/100-$J5-pd_pay30*Q$3*lgd_pay30/100*ead_pay30/100/100-opex_pct*opex_y3_mult/100)+(disb_y3*advance_rate/100*tenor_bnpl/365*mix_bnpl/100)*(fee_bnpl_mo*12/100-$J5-pd_bnpl*Q$3*lgd_bnpl/100*ead_bnpl/100/100-opex_pct*opex_y3_mult/100)+(disb_y3*advance_rate/100*tenor_ext/365*mix_ext/100)*(fee_ext_apr/100-$J5-pd_ext*Q$3*lgd_ext/100*ead_ext/100/100-opex_pct*opex_y3_mult/100) -> 28.077041 | J5: 0.055
A6: COF 6.0% | B6: =(disb_y3*advance_rate/100*tenor_pay30/365*mix_pay30/100)*(fee_pay30_mo*12/100-$J6-pd_pay30*K$3*lgd_pay30/100*ead_pay30/100/100-opex_pct*opex_y3_mult/100)+(disb_y3*advance_rate/100*tenor_bnpl/365*mix_bnpl/100)*(fee_bnpl_mo*12/100-$J6-pd_bnpl*K$3*lgd_bnpl/100*ead_bnpl/100/100-opex_pct*opex_y3_mult/100)+(disb_y3*advance_rate/100*tenor_ext/365*mix_ext/100)*(fee_ext_apr/100-$J6-pd_ext*K$3*lgd_ext/100*ead_ext/100/100-opex_pct*opex_y3_mult/100) -> 58.710575 | C6: =(disb_y3*advance_rate/100*tenor_pay30/365*mix_pay30/100)*(fee_pay30_mo*12/100-$J6-pd_pay30*L$3*lgd_pay30/100*ead_pay30/100/100-opex_pct*opex_y3_mult/100)+(disb_y3*advance_rate/100*tenor_bnpl/365*mix_bnpl/100)*(fee_bnpl_mo*12/100-$J6-pd_bnpl*L$3*lgd_bnpl/100*ead_bnpl/100/100-opex_pct*opex_y3_mult/100)+(disb_y3*advance_rate/100*tenor_ext/365*mix_ext/100)*(fee_ext_apr/100-$J6-pd_ext*L$3*lgd_ext/100*ead_ext/100/100-opex_pct*opex_y3_mult/100) -> 54.372822 | D6: =(disb_y3*advance_rate/100*tenor_pay30/365*mix_pay30/100)*(fee_pay30_mo*12/100-$J6-pd_pay30*M$3*lgd_pay30/100*ead_pay30/100/100-opex_pct*opex_y3_mult/100)+(disb_y3*advance_rate/100*tenor_bnpl/365*mix_bnpl/100)*(fee_bnpl_mo*12/100-$J6-pd_bnpl*M$3*lgd_bnpl/100*ead_bnpl/100/100-opex_pct*opex_y3_mult/100)+(disb_y3*advance_rate/100*tenor_ext/365*mix_ext/100)*(fee_ext_apr/100-$J6-pd_ext*M$3*lgd_ext/100*ead_ext/100/100-opex_pct*opex_y3_mult/100) -> 50.035068 | E6: =(disb_y3*advance_rate/100*tenor_pay30/365*mix_pay30/100)*(fee_pay30_mo*12/100-$J6-pd_pay30*N$3*lgd_pay30/100*ead_pay30/100/100-opex_pct*opex_y3_mult/100)+(disb_y3*advance_rate/100*tenor_bnpl/365*mix_bnpl/100)*(fee_bnpl_mo*12/100-$J6-pd_bnpl*N$3*lgd_bnpl/100*ead_bnpl/100/100-opex_pct*opex_y3_mult/100)+(disb_y3*advance_rate/100*tenor_ext/365*mix_ext/100)*(fee_ext_apr/100-$J6-pd_ext*N$3*lgd_ext/100*ead_ext/100/100-opex_pct*opex_y3_mult/100) -> 45.697315 | F6: =(disb_y3*advance_rate/100*tenor_pay30/365*mix_pay30/100)*(fee_pay30_mo*12/100-$J6-pd_pay30*O$3*lgd_pay30/100*ead_pay30/100/100-opex_pct*opex_y3_mult/100)+(disb_y3*advance_rate/100*tenor_bnpl/365*mix_bnpl/100)*(fee_bnpl_mo*12/100-$J6-pd_bnpl*O$3*lgd_bnpl/100*ead_bnpl/100/100-opex_pct*opex_y3_mult/100)+(disb_y3*advance_rate/100*tenor_ext/365*mix_ext/100)*(fee_ext_apr/100-$J6-pd_ext*O$3*lgd_ext/100*ead_ext/100/100-opex_pct*opex_y3_mult/100) -> 39.190685 | G6: =(disb_y3*advance_rate/100*tenor_pay30/365*mix_pay30/100)*(fee_pay30_mo*12/100-$J6-pd_pay30*P$3*lgd_pay30/100*ead_pay30/100/100-opex_pct*opex_y3_mult/100)+(disb_y3*advance_rate/100*tenor_bnpl/365*mix_bnpl/100)*(fee_bnpl_mo*12/100-$J6-pd_bnpl*P$3*lgd_bnpl/100*ead_bnpl/100/100-opex_pct*opex_y3_mult/100)+(disb_y3*advance_rate/100*tenor_ext/365*mix_ext/100)*(fee_ext_apr/100-$J6-pd_ext*P$3*lgd_ext/100*ead_ext/100/100-opex_pct*opex_y3_mult/100) -> 32.684055 | H6: =(disb_y3*advance_rate/100*tenor_pay30/365*mix_pay30/100)*(fee_pay30_mo*12/100-$J6-pd_pay30*Q$3*lgd_pay30/100*ead_pay30/100/100-opex_pct*opex_y3_mult/100)+(disb_y3*advance_rate/100*tenor_bnpl/365*mix_bnpl/100)*(fee_bnpl_mo*12/100-$J6-pd_bnpl*Q$3*lgd_bnpl/100*ead_bnpl/100/100-opex_pct*opex_y3_mult/100)+(disb_y3*advance_rate/100*tenor_ext/365*mix_ext/100)*(fee_ext_apr/100-$J6-pd_ext*Q$3*lgd_ext/100*ead_ext/100/100-opex_pct*opex_y3_mult/100) -> 24.008548 | J6: 0.06
A7: COF 6.5% | B7: =(disb_y3*advance_rate/100*tenor_pay30/365*mix_pay30/100)*(fee_pay30_mo*12/100-$J7-pd_pay30*K$3*lgd_pay30/100*ead_pay30/100/100-opex_pct*opex_y3_mult/100)+(disb_y3*advance_rate/100*tenor_bnpl/365*mix_bnpl/100)*(fee_bnpl_mo*12/100-$J7-pd_bnpl*K$3*lgd_bnpl/100*ead_bnpl/100/100-opex_pct*opex_y3_mult/100)+(disb_y3*advance_rate/100*tenor_ext/365*mix_ext/100)*(fee_ext_apr/100-$J7-pd_ext*K$3*lgd_ext/100*ead_ext/100/100-opex_pct*opex_y3_mult/100) -> 54.642082 | C7: =(disb_y3*advance_rate/100*tenor_pay30/365*mix_pay30/100)*(fee_pay30_mo*12/100-$J7-pd_pay30*L$3*lgd_pay30/100*ead_pay30/100/100-opex_pct*opex_y3_mult/100)+(disb_y3*advance_rate/100*tenor_bnpl/365*mix_bnpl/100)*(fee_bnpl_mo*12/100-$J7-pd_bnpl*L$3*lgd_bnpl/100*ead_bnpl/100/100-opex_pct*opex_y3_mult/100)+(disb_y3*advance_rate/100*tenor_ext/365*mix_ext/100)*(fee_ext_apr/100-$J7-pd_ext*L$3*lgd_ext/100*ead_ext/100/100-opex_pct*opex_y3_mult/100) -> 50.304329 | D7: =(disb_y3*advance_rate/100*tenor_pay30/365*mix_pay30/100)*(fee_pay30_mo*12/100-$J7-pd_pay30*M$3*lgd_pay30/100*ead_pay30/100/100-opex_pct*opex_y3_mult/100)+(disb_y3*advance_rate/100*tenor_bnpl/365*mix_bnpl/100)*(fee_bnpl_mo*12/100-$J7-pd_bnpl*M$3*lgd_bnpl/100*ead_bnpl/100/100-opex_pct*opex_y3_mult/100)+(disb_y3*advance_rate/100*tenor_ext/365*mix_ext/100)*(fee_ext_apr/100-$J7-pd_ext*M$3*lgd_ext/100*ead_ext/100/100-opex_pct*opex_y3_mult/100) -> 45.966575 | E7: =(disb_y3*advance_rate/100*tenor_pay30/365*mix_pay30/100)*(fee_pay30_mo*12/100-$J7-pd_pay30*N$3*lgd_pay30/100*ead_pay30/100/100-opex_pct*opex_y3_mult/100)+(disb_y3*advance_rate/100*tenor_bnpl/365*mix_bnpl/100)*(fee_bnpl_mo*12/100-$J7-pd_bnpl*N$3*lgd_bnpl/100*ead_bnpl/100/100-opex_pct*opex_y3_mult/100)+(disb_y3*advance_rate/100*tenor_ext/365*mix_ext/100)*(fee_ext_apr/100-$J7-pd_ext*N$3*lgd_ext/100*ead_ext/100/100-opex_pct*opex_y3_mult/100) -> 41.628822 | F7: =(disb_y3*advance_rate/100*tenor_pay30/365*mix_pay30/100)*(fee_pay30_mo*12/100-$J7-pd_pay30*O$3*lgd_pay30/100*ead_pay30/100/100-opex_pct*opex_y3_mult/100)+(disb_y3*advance_rate/100*tenor_bnpl/365*mix_bnpl/100)*(fee_bnpl_mo*12/100-$J7-pd_bnpl*O$3*lgd_bnpl/100*ead_bnpl/100/100-opex_pct*opex_y3_mult/100)+(disb_y3*advance_rate/100*tenor_ext/365*mix_ext/100)*(fee_ext_apr/100-$J7-pd_ext*O$3*lgd_ext/100*ead_ext/100/100-opex_pct*opex_y3_mult/100) -> 35.122192 | G7: =(disb_y3*advance_rate/100*tenor_pay30/365*mix_pay30/100)*(fee_pay30_mo*12/100-$J7-pd_pay30*P$3*lgd_pay30/100*ead_pay30/100/100-opex_pct*opex_y3_mult/100)+(disb_y3*advance_rate/100*tenor_bnpl/365*mix_bnpl/100)*(fee_bnpl_mo*12/100-$J7-pd_bnpl*P$3*lgd_bnpl/100*ead_bnpl/100/100-opex_pct*opex_y3_mult/100)+(disb_y3*advance_rate/100*tenor_ext/365*mix_ext/100)*(fee_ext_apr/100-$J7-pd_ext*P$3*lgd_ext/100*ead_ext/100/100-opex_pct*opex_y3_mult/100) -> 28.615562 | H7: =(disb_y3*advance_rate/100*tenor_pay30/365*mix_pay30/100)*(fee_pay30_mo*12/100-$J7-pd_pay30*Q$3*lgd_pay30/100*ead_pay30/100/100-opex_pct*opex_y3_mult/100)+(disb_y3*advance_rate/100*tenor_bnpl/365*mix_bnpl/100)*(fee_bnpl_mo*12/100-$J7-pd_bnpl*Q$3*lgd_bnpl/100*ead_bnpl/100/100-opex_pct*opex_y3_mult/100)+(disb_y3*advance_rate/100*tenor_ext/365*mix_ext/100)*(fee_ext_apr/100-$J7-pd_ext*Q$3*lgd_ext/100*ead_ext/100/100-opex_pct*opex_y3_mult/100) -> 19.940055 | J7: 0.065
A8: COF 7.0% | B8: =(disb_y3*advance_rate/100*tenor_pay30/365*mix_pay30/100)*(fee_pay30_mo*12/100-$J8-pd_pay30*K$3*lgd_pay30/100*ead_pay30/100/100-opex_pct*opex_y3_mult/100)+(disb_y3*advance_rate/100*tenor_bnpl/365*mix_bnpl/100)*(fee_bnpl_mo*12/100-$J8-pd_bnpl*K$3*lgd_bnpl/100*ead_bnpl/100/100-opex_pct*opex_y3_mult/100)+(disb_y3*advance_rate/100*tenor_ext/365*mix_ext/100)*(fee_ext_apr/100-$J8-pd_ext*K$3*lgd_ext/100*ead_ext/100/100-opex_pct*opex_y3_mult/100) -> 50.573589 | C8: =(disb_y3*advance_rate/100*tenor_pay30/365*mix_pay30/100)*(fee_pay30_mo*12/100-$J8-pd_pay30*L$3*lgd_pay30/100*ead_pay30/100/100-opex_pct*opex_y3_mult/100)+(disb_y3*advance_rate/100*tenor_bnpl/365*mix_bnpl/100)*(fee_bnpl_mo*12/100-$J8-pd_bnpl*L$3*lgd_bnpl/100*ead_bnpl/100/100-opex_pct*opex_y3_mult/100)+(disb_y3*advance_rate/100*tenor_ext/365*mix_ext/100)*(fee_ext_apr/100-$J8-pd_ext*L$3*lgd_ext/100*ead_ext/100/100-opex_pct*opex_y3_mult/100) -> 46.235836 | D8: =(disb_y3*advance_rate/100*tenor_pay30/365*mix_pay30/100)*(fee_pay30_mo*12/100-$J8-pd_pay30*M$3*lgd_pay30/100*ead_pay30/100/100-opex_pct*opex_y3_mult/100)+(disb_y3*advance_rate/100*tenor_bnpl/365*mix_bnpl/100)*(fee_bnpl_mo*12/100-$J8-pd_bnpl*M$3*lgd_bnpl/100*ead_bnpl/100/100-opex_pct*opex_y3_mult/100)+(disb_y3*advance_rate/100*tenor_ext/365*mix_ext/100)*(fee_ext_apr/100-$J8-pd_ext*M$3*lgd_ext/100*ead_ext/100/100-opex_pct*opex_y3_mult/100) -> 41.898082 | E8: =(disb_y3*advance_rate/100*tenor_pay30/365*mix_pay30/100)*(fee_pay30_mo*12/100-$J8-pd_pay30*N$3*lgd_pay30/100*ead_pay30/100/100-opex_pct*opex_y3_mult/100)+(disb_y3*advance_rate/100*tenor_bnpl/365*mix_bnpl/100)*(fee_bnpl_mo*12/100-$J8-pd_bnpl*N$3*lgd_bnpl/100*ead_bnpl/100/100-opex_pct*opex_y3_mult/100)+(disb_y3*advance_rate/100*tenor_ext/365*mix_ext/100)*(fee_ext_apr/100-$J8-pd_ext*N$3*lgd_ext/100*ead_ext/100/100-opex_pct*opex_y3_mult/100) -> 37.560329 | F8: =(disb_y3*advance_rate/100*tenor_pay30/365*mix_pay30/100)*(fee_pay30_mo*12/100-$J8-pd_pay30*O$3*lgd_pay30/100*ead_pay30/100/100-opex_pct*opex_y3_mult/100)+(disb_y3*advance_rate/100*tenor_bnpl/365*mix_bnpl/100)*(fee_bnpl_mo*12/100-$J8-pd_bnpl*O$3*lgd_bnpl/100*ead_bnpl/100/100-opex_pct*opex_y3_mult/100)+(disb_y3*advance_rate/100*tenor_ext/365*mix_ext/100)*(fee_ext_apr/100-$J8-pd_ext*O$3*lgd_ext/100*ead_ext/100/100-opex_pct*opex_y3_mult/100) -> 31.053699 | G8: =(disb_y3*advance_rate/100*tenor_pay30/365*mix_pay30/100)*(fee_pay30_mo*12/100-$J8-pd_pay30*P$3*lgd_pay30/100*ead_pay30/100/100-opex_pct*opex_y3_mult/100)+(disb_y3*advance_rate/100*tenor_bnpl/365*mix_bnpl/100)*(fee_bnpl_mo*12/100-$J8-pd_bnpl*P$3*lgd_bnpl/100*ead_bnpl/100/100-opex_pct*opex_y3_mult/100)+(disb_y3*advance_rate/100*tenor_ext/365*mix_ext/100)*(fee_ext_apr/100-$J8-pd_ext*P$3*lgd_ext/100*ead_ext/100/100-opex_pct*opex_y3_mult/100) -> 24.547068 | H8: =(disb_y3*advance_rate/100*tenor_pay30/365*mix_pay30/100)*(fee_pay30_mo*12/100-$J8-pd_pay30*Q$3*lgd_pay30/100*ead_pay30/100/100-opex_pct*opex_y3_mult/100)+(disb_y3*advance_rate/100*tenor_bnpl/365*mix_bnpl/100)*(fee_bnpl_mo*12/100-$J8-pd_bnpl*Q$3*lgd_bnpl/100*ead_bnpl/100/100-opex_pct*opex_y3_mult/100)+(disb_y3*advance_rate/100*tenor_ext/365*mix_ext/100)*(fee_ext_apr/100-$J8-pd_ext*Q$3*lgd_ext/100*ead_ext/100/100-opex_pct*opex_y3_mult/100) -> 15.871562 | J8: 0.07
A9: COF 7.5% | B9: =(disb_y3*advance_rate/100*tenor_pay30/365*mix_pay30/100)*(fee_pay30_mo*12/100-$J9-pd_pay30*K$3*lgd_pay30/100*ead_pay30/100/100-opex_pct*opex_y3_mult/100)+(disb_y3*advance_rate/100*tenor_bnpl/365*mix_bnpl/100)*(fee_bnpl_mo*12/100-$J9-pd_bnpl*K$3*lgd_bnpl/100*ead_bnpl/100/100-opex_pct*opex_y3_mult/100)+(disb_y3*advance_rate/100*tenor_ext/365*mix_ext/100)*(fee_ext_apr/100-$J9-pd_ext*K$3*lgd_ext/100*ead_ext/100/100-opex_pct*opex_y3_mult/100) -> 46.505096 | C9: =(disb_y3*advance_rate/100*tenor_pay30/365*mix_pay30/100)*(fee_pay30_mo*12/100-$J9-pd_pay30*L$3*lgd_pay30/100*ead_pay30/100/100-opex_pct*opex_y3_mult/100)+(disb_y3*advance_rate/100*tenor_bnpl/365*mix_bnpl/100)*(fee_bnpl_mo*12/100-$J9-pd_bnpl*L$3*lgd_bnpl/100*ead_bnpl/100/100-opex_pct*opex_y3_mult/100)+(disb_y3*advance_rate/100*tenor_ext/365*mix_ext/100)*(fee_ext_apr/100-$J9-pd_ext*L$3*lgd_ext/100*ead_ext/100/100-opex_pct*opex_y3_mult/100) -> 42.167342 | D9: =(disb_y3*advance_rate/100*tenor_pay30/365*mix_pay30/100)*(fee_pay30_mo*12/100-$J9-pd_pay30*M$3*lgd_pay30/100*ead_pay30/100/100-opex_pct*opex_y3_mult/100)+(disb_y3*advance_rate/100*tenor_bnpl/365*mix_bnpl/100)*(fee_bnpl_mo*12/100-$J9-pd_bnpl*M$3*lgd_bnpl/100*ead_bnpl/100/100-opex_pct*opex_y3_mult/100)+(disb_y3*advance_rate/100*tenor_ext/365*mix_ext/100)*(fee_ext_apr/100-$J9-pd_ext*M$3*lgd_ext/100*ead_ext/100/100-opex_pct*opex_y3_mult/100) -> 37.829589 | E9: =(disb_y3*advance_rate/100*tenor_pay30/365*mix_pay30/100)*(fee_pay30_mo*12/100-$J9-pd_pay30*N$3*lgd_pay30/100*ead_pay30/100/100-opex_pct*opex_y3_mult/100)+(disb_y3*advance_rate/100*tenor_bnpl/365*mix_bnpl/100)*(fee_bnpl_mo*12/100-$J9-pd_bnpl*N$3*lgd_bnpl/100*ead_bnpl/100/100-opex_pct*opex_y3_mult/100)+(disb_y3*advance_rate/100*tenor_ext/365*mix_ext/100)*(fee_ext_apr/100-$J9-pd_ext*N$3*lgd_ext/100*ead_ext/100/100-opex_pct*opex_y3_mult/100) -> 33.491836 | F9: =(disb_y3*advance_rate/100*tenor_pay30/365*mix_pay30/100)*(fee_pay30_mo*12/100-$J9-pd_pay30*O$3*lgd_pay30/100*ead_pay30/100/100-opex_pct*opex_y3_mult/100)+(disb_y3*advance_rate/100*tenor_bnpl/365*mix_bnpl/100)*(fee_bnpl_mo*12/100-$J9-pd_bnpl*O$3*lgd_bnpl/100*ead_bnpl/100/100-opex_pct*opex_y3_mult/100)+(disb_y3*advance_rate/100*tenor_ext/365*mix_ext/100)*(fee_ext_apr/100-$J9-pd_ext*O$3*lgd_ext/100*ead_ext/100/100-opex_pct*opex_y3_mult/100) -> 26.985205 | G9: =(disb_y3*advance_rate/100*tenor_pay30/365*mix_pay30/100)*(fee_pay30_mo*12/100-$J9-pd_pay30*P$3*lgd_pay30/100*ead_pay30/100/100-opex_pct*opex_y3_mult/100)+(disb_y3*advance_rate/100*tenor_bnpl/365*mix_bnpl/100)*(fee_bnpl_mo*12/100-$J9-pd_bnpl*P$3*lgd_bnpl/100*ead_bnpl/100/100-opex_pct*opex_y3_mult/100)+(disb_y3*advance_rate/100*tenor_ext/365*mix_ext/100)*(fee_ext_apr/100-$J9-pd_ext*P$3*lgd_ext/100*ead_ext/100/100-opex_pct*opex_y3_mult/100) -> 20.478575 | H9: =(disb_y3*advance_rate/100*tenor_pay30/365*mix_pay30/100)*(fee_pay30_mo*12/100-$J9-pd_pay30*Q$3*lgd_pay30/100*ead_pay30/100/100-opex_pct*opex_y3_mult/100)+(disb_y3*advance_rate/100*tenor_bnpl/365*mix_bnpl/100)*(fee_bnpl_mo*12/100-$J9-pd_bnpl*Q$3*lgd_bnpl/100*ead_bnpl/100/100-opex_pct*opex_y3_mult/100)+(disb_y3*advance_rate/100*tenor_ext/365*mix_ext/100)*(fee_ext_apr/100-$J9-pd_ext*Q$3*lgd_ext/100*ead_ext/100/100-opex_pct*opex_y3_mult/100) -> 11.803068 | J9: 0.075
A10: COF 8.0% | B10: =(disb_y3*advance_rate/100*tenor_pay30/365*mix_pay30/100)*(fee_pay30_mo*12/100-$J10-pd_pay30*K$3*lgd_pay30/100*ead_pay30/100/100-opex_pct*opex_y3_mult/100)+(disb_y3*advance_rate/100*tenor_bnpl/365*mix_bnpl/100)*(fee_bnpl_mo*12/100-$J10-pd_bnpl*K$3*lgd_bnpl/100*ead_bnpl/100/100-opex_pct*opex_y3_mult/100)+(disb_y3*advance_rate/100*tenor_ext/365*mix_ext/100)*(fee_ext_apr/100-$J10-pd_ext*K$3*lgd_ext/100*ead_ext/100/100-opex_pct*opex_y3_mult/100) -> 42.436603 | C10: =(disb_y3*advance_rate/100*tenor_pay30/365*mix_pay30/100)*(fee_pay30_mo*12/100-$J10-pd_pay30*L$3*lgd_pay30/100*ead_pay30/100/100-opex_pct*opex_y3_mult/100)+(disb_y3*advance_rate/100*tenor_bnpl/365*mix_bnpl/100)*(fee_bnpl_mo*12/100-$J10-pd_bnpl*L$3*lgd_bnpl/100*ead_bnpl/100/100-opex_pct*opex_y3_mult/100)+(disb_y3*advance_rate/100*tenor_ext/365*mix_ext/100)*(fee_ext_apr/100-$J10-pd_ext*L$3*lgd_ext/100*ead_ext/100/100-opex_pct*opex_y3_mult/100) -> 38.098849 | D10: =(disb_y3*advance_rate/100*tenor_pay30/365*mix_pay30/100)*(fee_pay30_mo*12/100-$J10-pd_pay30*M$3*lgd_pay30/100*ead_pay30/100/100-opex_pct*opex_y3_mult/100)+(disb_y3*advance_rate/100*tenor_bnpl/365*mix_bnpl/100)*(fee_bnpl_mo*12/100-$J10-pd_bnpl*M$3*lgd_bnpl/100*ead_bnpl/100/100-opex_pct*opex_y3_mult/100)+(disb_y3*advance_rate/100*tenor_ext/365*mix_ext/100)*(fee_ext_apr/100-$J10-pd_ext*M$3*lgd_ext/100*ead_ext/100/100-opex_pct*opex_y3_mult/100) -> 33.761096 | E10: =(disb_y3*advance_rate/100*tenor_pay30/365*mix_pay30/100)*(fee_pay30_mo*12/100-$J10-pd_pay30*N$3*lgd_pay30/100*ead_pay30/100/100-opex_pct*opex_y3_mult/100)+(disb_y3*advance_rate/100*tenor_bnpl/365*mix_bnpl/100)*(fee_bnpl_mo*12/100-$J10-pd_bnpl*N$3*lgd_bnpl/100*ead_bnpl/100/100-opex_pct*opex_y3_mult/100)+(disb_y3*advance_rate/100*tenor_ext/365*mix_ext/100)*(fee_ext_apr/100-$J10-pd_ext*N$3*lgd_ext/100*ead_ext/100/100-opex_pct*opex_y3_mult/100) -> 29.423342 | F10: =(disb_y3*advance_rate/100*tenor_pay30/365*mix_pay30/100)*(fee_pay30_mo*12/100-$J10-pd_pay30*O$3*lgd_pay30/100*ead_pay30/100/100-opex_pct*opex_y3_mult/100)+(disb_y3*advance_rate/100*tenor_bnpl/365*mix_bnpl/100)*(fee_bnpl_mo*12/100-$J10-pd_bnpl*O$3*lgd_bnpl/100*ead_bnpl/100/100-opex_pct*opex_y3_mult/100)+(disb_y3*advance_rate/100*tenor_ext/365*mix_ext/100)*(fee_ext_apr/100-$J10-pd_ext*O$3*lgd_ext/100*ead_ext/100/100-opex_pct*opex_y3_mult/100) -> 22.916712 | G10: =(disb_y3*advance_rate/100*tenor_pay30/365*mix_pay30/100)*(fee_pay30_mo*12/100-$J10-pd_pay30*P$3*lgd_pay30/100*ead_pay30/100/100-opex_pct*opex_y3_mult/100)+(disb_y3*advance_rate/100*tenor_bnpl/365*mix_bnpl/100)*(fee_bnpl_mo*12/100-$J10-pd_bnpl*P$3*lgd_bnpl/100*ead_bnpl/100/100-opex_pct*opex_y3_mult/100)+(disb_y3*advance_rate/100*tenor_ext/365*mix_ext/100)*(fee_ext_apr/100-$J10-pd_ext*P$3*lgd_ext/100*ead_ext/100/100-opex_pct*opex_y3_mult/100) -> 16.410082 | H10: =(disb_y3*advance_rate/100*tenor_pay30/365*mix_pay30/100)*(fee_pay30_mo*12/100-$J10-pd_pay30*Q$3*lgd_pay30/100*ead_pay30/100/100-opex_pct*opex_y3_mult/100)+(disb_y3*advance_rate/100*tenor_bnpl/365*mix_bnpl/100)*(fee_bnpl_mo*12/100-$J10-pd_bnpl*Q$3*lgd_bnpl/100*ead_bnpl/100/100-opex_pct*opex_y3_mult/100)+(disb_y3*advance_rate/100*tenor_ext/365*mix_ext/100)*(fee_ext_apr/100-$J10-pd_ext*Q$3*lgd_ext/100*ead_ext/100/100-opex_pct*opex_y3_mult/100) -> 7.7345753 | J10: 0.08
